Workbook

Sheet Допущения
A1: Радити — допущения юнит-экономики
A2: Синие значения — входные данные, их можно менять. Жёлтая заливка — ключевые допущения, которые проверяем в пилоте. Чёрные — формулы.
A4: Цены моделей, ₽ за 1 млн токенов с НДС
A5: Стандартная модель (Qwen3-Coder-Next, Cloud.ru): вход | B5: 122 | C5: ₽/1 млн | D5: Cloud.ru, тарифы Evolution Foundation Models 260915: 100 ₽ без НДС × 1,22. https://cdn.cloud.ru/docs/legal/tariffs/evolution/future-version/foundation-models.pdf
A6: Стандартная модель: выход | B6: 244 | C6: ₽/1 млн | D6: Там же: 200 ₽ без НДС × 1,22
A7: Сложная модель (GLM-5.1, Cloud.ru): вход | B7: 198.86 | C7: ₽/1 млн | D7: Там же: 163 ₽ без НДС × 1,22
A8: Сложная модель: выход | B8: 829.6 | C8: ₽/1 млн | D8: Там же: 680 ₽ без НДС × 1,22
A9: Служебная модель (gpt-oss-120b, Cloud.ru): вход | B9: 15.86 | C9: ₽/1 млн | D9: Там же: 13 ₽ без НДС × 1,22
A10: Служебная модель: выход | B10: 61 | C10: ₽/1 млн | D10: Там же: 50 ₽ без НДС × 1,22
A12: Профиль задач
A13: Доля контентных задач | B13: 0.6 | D13: Гипотеза до пилота
A14: Доля задач с кодом | B14: 0.32 | D14: Гипотеза до пилота
A15: Доля сложных задач | B15: =1-B13-B14 -> 0.08 | D15: Остаток до 100%
A16: Контент: токены на входе | B16: 250000 | C16: токенов | D16: Оценка для агентного CLI: контекст пересылается на каждом шаге; уточнить eval в PoC
A17: Контент: токены на выходе | B17: 5000 | C17: токенов | D17: Оценка
A18: Код: токены на входе | B18: 1200000 | C18: токенов | D18: Оценка; уточнить eval в PoC
A19: Код: токены на выходе | B19: 20000 | C19: токенов | D19: Оценка
A20: Сложная: токены на входе | B20: 2000000 | C20: токенов | D20: Оценка
A21: Сложная: токены на выходе | B21: 40000 | C21: токенов | D21: Оценка
A22: Служебные вызовы на задачу: вход | B22: 20000 | C22: токенов | D22: Классификация, сводки, сообщения клиенту
A23: Служебные вызовы на задачу: выход | B23: 2000 | C23: токенов | D23: Оценка
A24: Надбавка на повторы и неудачные попытки | B24: 0.25 | D24: Оценка
A25: Контент: минут в песочнице | B25: 3 | C25: мин | D25: Оценка
A26: Код: минут в песочнице | B26: 10 | C26: мин | D26: Оценка
A27: Сложная: минут в песочнице | B27: 20 | C27: мин | D27: Оценка
A29: Вычисления
A30: vCPU, ₽ в час с НДС | B30: 1.6358 | C30: ₽/ч | D30: Расчёт по Cloud.ru Evolution Compute 260619: ВМ 12 vCPU/24 ГБ = 23,7534 ₽/ч и 16 vCPU/128 ГБ = 48,1656 ₽/ч. https://cloud.ru/documents/tariffs/evolution/evolution-compute
A31: RAM, ₽ за ГБ в час с НДС | B31: 0.1718 | C31: ₽/ГБ·ч | D31: Там же
A32: Песочница: vCPU | B32: 2 | C32: vCPU | D32: Спецификация, раздел 8
A33: Песочница: RAM | B33: 4 | C33: ГБ | D33: Спецификация, раздел 8
A34: Браузер (скриншоты): минут на задачу | B34: 2 | C34: мин | D34: Оценка; 1 vCPU / 2 ГБ
A35: Раннер CI: минут на задачу с кодом | B35: 3 | C35: мин | D35: Оценка
A36: Загрузка зарезервированных мощностей | B36: 0.35 | D36: Оценка
A38: Оператор
A39: Зарплата оператора | B39: 120000 | C39: ₽/мес | D39: Оценка
A40: Коэффициент НДФЛ и взносов | B40: 1.24 | C40: × | D40: Оценка
A41: Рабочих дней в месяце | B41: 21 | C41: дней
A42: Часов в день | B42: 8 | C42: ч
A43: Доля продуктивного времени | B43: 0.7 | D43: Оценка
A44: Доля задач с эскалацией оператору | B44: 0.05 | D44: Гипотеза до пилота
...

Sheet Себестоимость
A1: Себестоимость задачи и клиента
A3: Контент: модель, ₽ | B3: =(Допущения!$B$16*Допущения!$B$5+Допущения!$B$17*Допущения!$B$6)/1000000 -> 31.72
A4: Код: модель, ₽ | B4: =(Допущения!$B$18*Допущения!$B$5+Допущения!$B$19*Допущения!$B$6)/1000000 -> 151.28
A5: Сложная: модель, ₽ | B5: =(Допущения!$B$20*Допущения!$B$7+Допущения!$B$21*Допущения!$B$8)/1000000 -> 430.904
A6: Служебные вызовы, ₽ | B6: =(Допущения!$B$22*Допущения!$B$9+Допущения!$B$23*Допущения!$B$10)/1000000 -> 0.4392
A7: Модели на среднюю задачу с повторами, ₽ | B7: =(Допущения!$B$13*Себестоимость!$B$3+Допущения!$B$14*Себестоимость!$B$4+Допущения!$B$15*Себестоимость!$B$5)*(1+Допущения!$B$24)+Себестоимость!$B$6 -> 127.8316
A8: Минут песочницы на среднюю задачу | B8: =Допущения!$B$13*Допущения!$B$25+Допущения!$B$14*Допущения!$B$26+Допущения!$B$15*Допущения!$B$27 -> 6.6
A9: Песочница, ₽ за минуту | B9: =(Допущения!$B$32*Допущения!$B$30+Допущения!$B$33*Допущения!$B$31)/60 -> 0.06598
A10: Вычисления на задачу (песочница, браузер, CI), ₽ | B10: =(Себестоимость!$B$8*Себестоимость!$B$9+Допущения!$B$34*(Допущения!$B$30+2*Допущения!$B$31)/60+(Допущения!$B$14+Допущения!$B$15)*Допущения!$B$35*Себестоимость!$B$9)/Допущения!$B$36 -> 1.6589257
A11: Минута оператора, ₽ | B11: =Допущения!$B$39*Допущения!$B$40/(Допущения!$B$41*Допущения!$B$42*60*Допущения!$B$43) -> 21.088435
A12: Эскалации на задачу, ₽ | B12: =Допущения!$B$44*Допущения!$B$45*Себестоимость!$B$11 -> 15.816327
A13: Себестоимость задачи, ₽ | B13: =Себестоимость!$B$7+Себестоимость!$B$10+Себестоимость!$B$12 -> 145.30685
A14: Онбординг клиента, ₽ | B14: =Допущения!$B$46*Себестоимость!$B$11 -> 632.65306
A15: Привлечение клиента с онбордингом, ₽ | B15: =Допущения!$B$54+Себестоимость!$B$14 -> 7632.6531

Sheet Тарифы
A1: Тарифы: себестоимость, вклад и цены по сценариям наценки
A3: Тариф | B3: Цена, ₽/мес | C3: Задач в среднем | D3: Сайтов в работе | E3: Доля клиентов | F3: Себестоимость без комиссии, ₽ | G3: Комиссия ЮKassa, ₽ | H3: Вклад, ₽ | I3: Маржа | J3: Наценка | K3: Квота, задач | L3: Себестоимость при полной квоте, ₽ | M3: Запас при полной квоте, ₽ | N3: Цена при наценке 1, ₽ | O3: Цена при наценке 2, ₽ | P3: Цена при наценке 3, ₽
A4: =Допущения!$A$79 -> Старт | B4: =Допущения!$B$79 -> 4900 | C4: =Допущения!$D$79 -> 12 | D4: =Допущения!$E$79 -> 1 | E4: =Допущения!$F$79 -> 0.7 | F4: =C4*Себестоимость!$B$13+D4*Допущения!$B$49*Допущения!$B$50 -> 1751.6822 | G4: =B4*Допущения!$B$51 -> 186.2 | H4: =B4-F4-G4 -> 2962.1178 | I4: =IF(B4=0,0,H4/B4) -> 0.60451383 | J4: =IF(F4+G4=0,0,H4/(F4+G4)) -> 1.5285334 | K4: =Допущения!$C$79 -> 30 | L4: =K4*Себестоимость!$B$13+D4*Допущения!$B$49*Допущения!$B$50+G4 -> 4553.4056 | M4: =B4-L4 -> 346.59443 | N4: =F4*(1+Допущения!$B$85)/(1-Допущения!$B$51*(1+Допущения!$B$85)) -> 2786.345 | O4: =F4*(1+Допущения!$B$86)/(1-Допущения!$B$51*(1+Допущения!$B$86)) -> 3384.5299 | P4: =F4*(1+Допущения!$B$87)/(1-Допущения!$B$51*(1+Допущения!$B$87)) -> 3791.52
A5: =Допущения!$A$80 -> Бизнес | B5: =Допущения!$B$80 -> 12900 | C5: =Допущения!$D$80 -> 40 | D5: =Допущения!$E$80 -> 1.5 | E5: =Допущения!$F$80 -> 0.25 | F5: =C5*Себестоимость!$B$13+D5*Допущения!$B$49*Допущения!$B$50 -> 5824.2741 | G5: =B5*Допущения!$B$51 -> 490.2 | H5: =B5-F5-G5 -> 6585.5259 | I5: =IF(B5=0,0,H5/B5) -> 0.51050588 | J5: =IF(F5+G5=0,0,H5/(F5+G5)) -> 1.0429255 | K5: =Допущения!$C$80 -> 80 | L5: =K5*Себестоимость!$B$13+D5*Допущения!$B$49*Допущения!$B$50+G5 -> 12126.748 | M5: =B5-L5 -> 773.25182 | N5: =F5*(1+Допущения!$B$85)/(1-Допущения!$B$51*(1+Допущения!$B$85)) -> 9264.4869 | O5: =F5*(1+Допущения!$B$86)/(1-Допущения!$B$51*(1+Допущения!$B$86)) -> 11253.428 | P5: =F5*(1+Допущения!$B$87)/(1-Допущения!$B$51*(1+Допущения!$B$87)) -> 12606.654
A6: =Допущения!$A$81 -> Агентство | B6: =Допущения!$B$81 -> 39900 | C6: =Допущения!$D$81 -> 150 | D6: =Допущения!$E$81 -> 8 | E6: =Допущения!$F$81 -> 0.05 | F6: =C6*Себестоимость!$B$13+D6*Допущения!$B$49*Допущения!$B$50 -> 21860.028 | G6: =B6*Допущения!$B$51 -> 1516.2 | H6: =B6-F6-G6 -> 16523.772 | I6: =IF(B6=0,0,H6/B6) -> 0.41412963 | J6: =IF(F6+G6=0,0,H6/(F6+G6)) -> 0.70686221 | K6: =Допущения!$C$81 -> 250 | L6: =K6*Себестоимость!$B$13+D6*Допущения!$B$49*Допущения!$B$50+G6 -> 37906.913 | M6: =B6-L6 -> 1993.0869 | N6: =F6*(1+Допущения!$B$85)/(1-Допущения!$B$51*(1+Допущения!$B$85)) -> 34772.049 | O6: =F6*(1+Допущения!$B$86)/(1-Допущения!$B$51*(1+Допущения!$B$86)) -> 42237.065 | P6: =F6*(1+Допущения!$B$87)/(1-Допущения!$B$51*(1+Допущения!$B$87)) -> 47316.078
A7: Средний клиент | B7: =SUMPRODUCT($E$4:$E$6,B4:B6) -> 8650 | C7: =SUMPRODUCT($E$4:$E$6,C4:C6) -> 25.9 | D7: =SUMPRODUCT($E$4:$E$6,D4:D6) -> 1.475 | E7: =SUM(E4:E6) -> 1 | F7: =SUMPRODUCT($E$4:$E$6,F4:F6) -> 3775.2475 | G7: =SUMPRODUCT($E$4:$E$6,G4:G6) -> 328.7 | H7: =SUMPRODUCT($E$4:$E$6,H4:H6) -> 4546.0525 | I7: =IF(B7=0,0,H7/B7) -> 0.52555521 | J7: =IF(F7+G7=0,0,H7/(F7+G7)) -> 1.1077268
A9: Запас при полной квоте ≥ 0: даже клиент, выбравший всю квоту, не уводит тариф в минус. Квота «10 задач в день» (300 в месяц) стоила бы: | L9: =300*Себестоимость!$B$13 -> 43592.056

Sheet Сценарии
A1: Сценарии: безубыточность и план привлечения
A2: План: каждый месяц приводим одинаковое число клиентов, отток из «Допущений», реклама списывается в том же месяце; после заданного числа месяцев в минусе — ноль.
A4: Сценарий | B4: Средний чек, ₽ | C4: Переменные на клиента, ₽ | D4: Вклад клиента, ₽ | E4: Маржа | F4: Наценка | G4: Безубыточность, клиентов | H4: С заменой оттока, клиентов | I4: Коэффициент накопления k | J4: Приводить в месяц, клиентов | K4: Клиентов к месяцу выхода в ноль | L4: Минус за месяцы в минусе, ₽ | M4: Реклама в месяц, ₽ | N4: Разработка до запуска, ₽ | O4: Нужно денег до выхода в ноль, ₽
A5: =CONCATENATE("Наценка ",TEXT(Допущения!$B$85,"0%")) -> Наценка 50% | B5: =SUMPRODUCT(Тарифы!$E$4:$E$6,Тарифы!N4:N6) -> 6005.1657 | C5: =SUMPRODUCT(Тарифы!$E$4:$E$6,Тарифы!$F$4:$F$6)+B5*Допущения!$B$51 -> 4003.4438 | D5: =B5-C5 -> 2001.7219 | E5: =IF(B5=0,0,D5/B5) -> 0.33333333 | F5: =IF(C5=0,0,D5/C5) -> 0.5 | G5: =IF(D5<=0,"нет",Допущения!$B$75/D5) -> 586.97311 | H5: =IF(D5-Допущения!$B$55*Себестоимость!$B$15<=0,"нет",Допущения!$B$75/(D5-Допущения!$B$55*Себестоимость!$B$15)) -> 692.61141 | I5: =(1-(1-Допущения!$B$55)^(Допущения!$B$56+1))/Допущения!$B$55 -> 3.766336 | J5: =IF(I5*D5-Себестоимость!$B$15<=0,"не окупается",Допущения!$B$75/(I5*D5-Себестоимость!$B$15)) -> не окупается | K5: =IF(ISNUMBER(J5),J5*I5,"—") -> — | L5: =IF(ISNUMBER(J5),D5*J5/Допущения!$B$55*(Допущения!$B$56-(1-Допущения!$B$55)*(1-(1-Допущения!$B$55)^Допущения!$B$56)/Допущения!$B$55)-Допущения!$B$56*Допущения!$B$75-Допущения!$B$56*J5*Себестоимость!$B$15,"—") -> — | M5: =IF(ISNUMBER(J5),J5*Себестоимость!$B$15,"—") -> — | N5: =Допущения!$B$57/4.345*Допущения!$B$75 -> 3785822 | O5: =IF(ISNUMBER(L5),N5-L5,"—") -> —
A6: =CONCATENATE("Наценка ",TEXT(Допущения!$B$86,"0%")) -> Наценка 80% | B6: =SUMPRODUCT(Тарифы!$E$4:$E$6,Тарифы!O4:O6) -> 7294.3811 | C6: =SUMPRODUCT(Тарифы!$E$4:$E$6,Тарифы!$F$4:$F$6)+B6*Допущения!$B$51 -> 4052.434 | D6: =B6-C6 -> 3241.9472 | E6: =IF(B6=0,0,D6/B6) -> 0.44444444 | F6: =IF(C6=0,0,D6/C6) -> 0.8 | G6: =IF(D6<=0,"нет",Допущения!$B$75/D6) -> 362.42321 | H6: =IF(D6-Допущения!$B$55*Себестоимость!$B$15<=0,"нет",Допущения!$B$75/(D6-Допущения!$B$55*Себестоимость!$B$15)) -> 400.10233 | I6: =(1-(1-Допущения!$B$55)^(Допущения!$B$56+1))/Допущения!$B$55 -> 3.766336 | J6: =IF(I6*D6-Себестоимость!$B$15<=0,"не окупается",Допущения!$B$75/(I6*D6-Себестоимость!$B$15)) -> 256.67479 | K6: =IF(ISNUMBER(J6),J6*I6,"—") -> 966.72352 | L6: =IF(ISNUMBER(J6),D6*J6/Допущения!$B$55*(Допущения!$B$56-(1-Допущения!$B$55)*(1-(1-Допущения!$B$55)^Допущения!$B$56)/Допущения!$B$55)-Допущения!$B$56*Допущения!$B$75-Допущения!$B$56*J6*Себестоимость!$B$15,"—") -> -4541251.8 | M6: =IF(ISNUMBER(J6),J6*Себестоимость!$B$15,"—") -> 1959109.7 | N6: =Допущения!$B$57/4.345*Допущения!$B$75 -> 3785822 | O6: =IF(ISNUMBER(L6),N6-L6,"—") -> 8327073.8
A7: =CONCATENATE("Наценка ",TEXT(Допущения!$B$87,"0%")) -> Наценка 100% | B7: =SUMPRODUCT(Тарифы!$E$4:$E$6,Тарифы!P4:P6) -> 8171.5313 | C7: =SUMPRODUCT(Тарифы!$E$4:$E$6,Тарифы!$F$4:$F$6)+B7*Допущения!$B$51 -> 4085.7657 | D7: =B7-C7 -> 4085.7657 | E7: =IF(B7=0,0,D7/B7) -> 0.5 | F7: =IF(C7=0,0,D7/C7) -> 1 | G7: =IF(D7<=0,"нет",Допущения!$B$75/D7) -> 287.57325 | H7: =IF(D7-Допущения!$B$55*Себестоимость!$B$15<=0,"нет",Допущения!$B$75/(D7-Допущения!$B$55*Себестоимость!$B$15)) -> 310.79738 | I7: =(1-(1-Допущения!$B$55)^(Допущения!$B$56+1))/Допущения!$B$55 -> 3.766336 | J7: =IF(I7*D7-Себестоимость!$B$15<=0,"не окупается",Допущения!$B$75/(I7*D7-Себестоимость!$B$15)) -> 151.49566 | K7: =IF(ISNUMBER(J7),J7*I7,"—") -> 570.58357 | L7: =IF(ISNUMBER(J7),D7*J7/Допущения!$B$55*(Допущения!$B$56-(1-Допущения!$B$55)*(1-(1-Допущения!$B$55)^Допущения!$B$56)/Допущения!$B$55)-Допущения!$B$56*Допущения!$B$75-Допущения!$B$56*J7*Себестоимость!$B$15,"—") -> -3378003.3 | M7: =IF(ISNUMBER(J7),J7*Себестоимость!$B$15,"—") -> 1156313.8 | N7: =Допущения!$B$57/4.345*Допущения!$B$75 -> 3785822 | O7: =IF(ISNUMBER(L7),N7-L7,"—") -> 7163825.4
A8: Цены от конкурентов | B8: =SUMPRODUCT(Тарифы!$E$4:$E$6,Тарифы!B4:B6) -> 8650 | C8: =SUMPRODUCT(Тарифы!$E$4:$E$6,Тарифы!$F$4:$F$6)+B8*Допущения!$B$51 -> 4103.9475 | D8: =B8-C8 -> 4546.0525 | E8: =IF(B8=0,0,D8/B8) -> 0.52555521 | F8: =IF(C8=0,0,D8/C8) -> 1.1077268 | G8: =IF(D8<=0,"нет",Допущения!$B$75/D8) -> 258.45652 | H8: =IF(D8-Допущения!$B$55*Себестоимость!$B$15<=0,"нет",Допущения!$B$75/(D8-Допущения!$B$55*Себестоимость!$B$15)) -> 277.06371 | I8: =(1-(1-Допущения!$B$55)^(Допущения!$B$56+1))/Допущения!$B$55 -> 3.766336 | J8: =IF(I8*D8-Себестоимость!$B$15<=0,"не окупается",Допущения!$B$75/(I8*D8-Себестоимость!$B$15)) -> 123.81903 | K8: =IF(ISNUMBER(J8),J8*I8,"—") -> 466.34406 | L8: =IF(ISNUMBER(J8),D8*J8/Допущения!$B$55*(Допущения!$B$56-(1-Допущения!$B$55)*(1-(1-Допущения!$B$55)^Допущения!$B$56)/Допущения!$B$55)-Допущения!$B$56*Допущения!$B$75-Допущения!$B$56*J8*Себестоимость!$B$15,"—") -> -3071908.4 | M8: =IF(ISNUMBER(J8),J8*Себестоимость!$B$15,"—") -> 945067.68 | N8: =Допущения!$B$57/4.345*Допущения!$B$75 -> 3785822 | O8: =IF(ISNUMBER(L8),N8-L8,"—") -> 6857730.4
A10: Безубыточность = постоянные расходы / вклад клиента. k = 1 + (1−отток) + … — сколько клиенто-месяцев даёт один месяц привлечения к месяцу выхода в ноль. «Приводить в месяц» = постоянные / (k × вклад − привлечение).

Sheet План 12 мес
A1: План на 12 месяцев после запуска продаж
A3: Сценарий (1–4, строка на листе «Сценарии») | B3: 4
A4: Название сценария | B4: =INDEX(Сценарии!$A$5:$A$8,$B$3) -> Цены от конкурентов
A5: Свои новые клиенты в месяц (пусто — из сценария)
A6: Новых клиентов в месяц в расчёте | B6: =IF(ISBLANK($B$5),IF(ISNUMBER(INDEX(Сценарии!$J$5:$J$8,$B$3)),INDEX(Сценарии!$J$5:$J$8,$B$3),0),$B$5) -> 123.81903
A7: Средний чек, ₽ | B7: =INDEX(Сценарии!$B$5:$B$8,$B$3) -> 8650
A8: Переменные на клиента, ₽ | B8: =INDEX(Сценарии!$C$5:$C$8,$B$3) -> 4103.9475
A10: Месяц | B10: Новые клиенты | C10: Активные клиенты | D10: Выручка, ₽ | E10: Переменные расходы, ₽ | F10: Постоянные расходы, ₽ | G10: Реклама и онбординг, ₽ | H10: Прибыль за месяц, ₽ | I10: Накоплено, ₽
A11: 1 | B11: =$B$6 -> 123.81903 | C11: =0*(1-Допущения!$B$55)+B11 -> 123.81903 | D11: =C11*$B$7 -> 1071034.6 | E11: =C11*$B$8 -> 508146.78 | F11: =Допущения!$B$75 -> 1174956.9 | G11: =B11*Себестоимость!$B$15 -> 945067.68 | H11: =D11-E11-F11-G11 -> -1557136.8 | I11: =0+H11 -> -1557136.8
A12: 2 | B12: =$B$6 -> 123.81903 | C12: =C11*(1-Допущения!$B$55)+B12 -> 242.68529 | D12: =C12*$B$7 -> 2099227.8 | E12: =C12*$B$8 -> 995967.7 | F12: =Допущения!$B$75 -> 1174956.9 | G12: =B12*Себестоимость!$B$15 -> 945067.68 | H12: =D12-E12-F12-G12 -> -1016764.5 | I12: =I11+H12 -> -2573901.3
A13: 3 | B13: =$B$6 -> 123.81903 | C13: =C12*(1-Допущения!$B$55)+B13 -> 356.79691 | D13: =C13*$B$7 -> 3086293.3 | E13: =C13*$B$8 -> 1464275.8 | F13: =Допущения!$B$75 -> 1174956.9 | G13: =B13*Себестоимость!$B$15 -> 945067.68 | H13: =D13-E13-F13-G13 -> -498007.1 | I13: =I12+H13 -> -3071908.4
A14: 4 | B14: =$B$6 -> 123.81903 | C14: =C13*(1-Допущения!$B$55)+B14 -> 466.34406 | D14: =C14*$B$7 -> 4033876.1 | E14: =C14*$B$8 -> 1913851.5 | F14: =Допущения!$B$75 -> 1174956.9 | G14: =B14*Себестоимость!$B$15 -> 945067.68 | H14: =D14-E14-F14-G14 -> 0 | I14: =I13+H14 -> -3071908.4
A15: 5 | B15: =$B$6 -> 123.81903 | C15: =C14*(1-Допущения!$B$55)+B15 -> 571.50932 | D15: =C15*$B$7 -> 4943555.7 | E15: =C15*$B$8 -> 2345444.2 | F15: =Допущения!$B$75 -> 1174956.9 | G15: =B15*Себестоимость!$B$15 -> 945067.68 | H15: =D15-E15-F15-G15 -> 478086.82 | I15: =I14+H15 -> -2593821.6
A16: 6 | B16: =$B$6 -> 123.81903 | C16: =C15*(1-Допущения!$B$55)+B16 -> 672.46798 | D16: =C16*$B$7 -> 5816848 | E16: =C16*$B$8 -> 2759773.3 | F16: =Допущения!$B$75 -> 1174956.9 | G16: =B16*Себестоимость!$B$15 -> 945067.68 | H16: =D16-E16-F16-G16 -> 937050.16 | I16: =I15+H16 -> -1656771.4
A17: 7 | B17: =$B$6 -> 123.81903 | C17: =C16*(1-Допущения!$B$55)+B17 -> 769.38829 | D17: =C17*$B$7 -> 6655208.7 | E17: =C17*$B$8 -> 3157529.1 | F17: =Допущения!$B$75 -> 1174956.9 | G17: =B17*Себестоимость!$B$15 -> 945067.68 | H17: =D17-E17-F17-G17 -> 1377655 | I17: =I16+H17 -> -279116.44
A18: 8 | B18: =$B$6 -> 123.81903 | C18: =C17*(1-Допущения!$B$55)+B18 -> 862.43178 | D18: =C18*$B$7 -> 7460034.9 | E18: =C18*$B$8 -> 3539374.7 | F18: =Допущения!$B$75 -> 1174956.9 | G18: =B18*Себестоимость!$B$15 -> 945067.68 | H18: =D18-E18-F18-G18 -> 1800635.6 | I18: =I17+H18 -> 1521519.2
A19: 9 | B19: =$B$6 -> 123.81903 | C19: =C18*(1-Допущения!$B$55)+B19 -> 951.75354 | D19: =C19*$B$7 -> 8232668.1 | E19: =C19*$B$8 -> 3905946.5 | F19: =Допущения!$B$75 -> 1174956.9 | G19: =B19*Себестоимость!$B$15 -> 945067.68 | H19: =D19-E19-F19-G19 -> 2206697 | I19: =I18+H19 -> 3728216.1
A20: 10 | B20: =$B$6 -> 123.81903 | C20: =C19*(1-Допущения!$B$55)+B20 -> 1037.5024 | D20: =C20*$B$7 -> 8974396 | E20: =C20*$B$8 -> 4257855.5 | F20: =Допущения!$B$75 -> 1174956.9 | G20: =B20*Себестоимость!$B$15 -> 945067.68 | H20: =D20-E20-F20-G20 -> 2596515.9 | I20: =I19+H20 -> 6324732.1
A21: 11 | B21: =$B$6 -> 123.81903 | C21: =C20*(1-Допущения!$B$55)+B21 -> 1119.8214 | D21: =C21*$B$7 -> 9686454.7 | E21: =C21*$B$8 -> 4595688 | F21: =Допущения!$B$75 -> 1174956.9 | G21: =B21*Себестоимость!$B$15 -> 945067.68 | H21: =D21-E21-F21-G21 -> 2970742.1 | I21: =I20+H21 -> 9295474.2
A22: 12 | B22: =$B$6 -> 123.81903 | C22: =C21*(1-Допущения!$B$55)+B22 -> 1198.8475 | D22: =C22*$B$7 -> 10370031 | E22: =C22*$B$8 -> 4920007.3 | F22: =Допущения!$B$75 -> 1174956.9 | G22: =B22*Себестоимость!$B$15 -> 945067.68 | H22: =D22-E22-F22-G22 -> 3329999.2 | I22: =I21+H22 -> 12625473
A24: Затраты на разработку до запуска (лист «Сценарии», столбец N) в накопленный итог не входят.

Sheet Железо
A1: Железо и модели на разных масштабах
A3: Рабочих дней в месяце с задачами | B3: 22
A4: Рабочих часов в день | B4: 10
A5: Пик к среднему | B5: 3
A6: Надбавка gVisor | B6: 1.2
A7: ВМ песочниц: vCPU | B7: 16
A8: ВМ песочниц: RAM, ГБ | B8: 32
A9: Доп. SSD на 100 клиентов, ГБ | B9: 50
A11: Показатель | B11: 100 клиентов | C11: 300 клиентов | D11: 1000 клиентов | E11: 3000 клиентов
A12: Клиентов | B12: 100 | C12: 300 | D12: 1000 | E12: 3000
A13: Задач в месяц | B13: =B12*Тарифы!$C$7 -> 2590 | C13: =C12*Тарифы!$C$7 -> 7770 | D13: =D12*Тарифы!$C$7 -> 25900 | E13: =E12*Тарифы!$C$7 -> 77700
A14: Песочниц в пик | B14: =B13*Себестоимость!$B$8/($B$3*$B$4*60)*$B$5 -> 3.885 | C14: =C13*Себестоимость!$B$8/($B$3*$B$4*60)*$B$5 -> 11.655 | D14: =D13*Себестоимость!$B$8/($B$3*$B$4*60)*$B$5 -> 38.85 | E14: =E13*Себестоимость!$B$8/($B$3*$B$4*60)*$B$5 -> 116.55
A15: ВМ песочниц | B15: =MAX(1,ROUNDUP(MAX(B14*Допущения!$B$32*$B$6/$B$7,B14*Допущения!$B$33*$B$6/$B$8),0)) -> 1 | C15: =MAX(1,ROUNDUP(MAX(C14*Допущения!$B$32*$B$6/$B$7,C14*Допущения!$B$33*$B$6/$B$8),0)) -> 2 | D15: =MAX(1,ROUNDUP(MAX(D14*Допущения!$B$32*$B$6/$B$7,D14*Допущения!$B$33*$B$6/$B$8),0)) -> 6 | E15: =MAX(1,ROUNDUP(MAX(E14*Допущения!$B$32*$B$6/$B$7,E14*Допущения!$B$33*$B$6/$B$8),0)) -> 18
A16: Узлов app и ci | B16: =1+INT(B12/1000) -> 1 | C16: =1+INT(C12/1000) -> 1 | D16: =1+INT(D12/1000) -> 2 | E16: =1+INT(E12/1000) -> 4
A17: Узлов gitea | B17: =1+INT(B12/3000) -> 1 | C17: =1+INT(C12/3000) -> 1 | D17: =1+INT(D12/3000) -> 1 | E17: =1+INT(E12/3000) -> 2
A18: vCPU всего | B18: =8*B16+4*B16+4*B17+2+$B$7*B15 -> 34 | C18: =8*C16+4*C16+4*C17+2+$B$7*C15 -> 50 | D18: =8*D16+4*D16+4*D17+2+$B$7*D15 -> 126 | E18: =8*E16+4*E16+4*E17+2+$B$7*E15 -> 346
A19: RAM всего, ГБ | B19: =16*B16+8*B16+8*B17+4+$B$8*B15 -> 68 | C19: =16*C16+8*C16+8*C17+4+$B$8*C15 -> 100 | D19: =16*D16+8*D16+8*D17+4+$B$8*D15 -> 252 | E19: =16*E16+8*E16+8*E17+4+$B$8*E15 -> 692
A20: Вычисления, ₽/мес | B20: =(B18*Допущения!$B$30+B19*Допущения!$B$31)*730 -> 49128.708 | C20: =(C18*Допущения!$B$30+C19*Допущения!$B$31)*730 -> 72248.1 | D20: =(D18*Допущения!$B$30+D19*Допущения!$B$31)*730 -> 182065.21 | E20: =(E18*Допущения!$B$30+E19*Допущения!$B$31)*730 -> 499956.85
A21: Диски, ₽/мес | B21: =(Допущения!$B$68+$B$9*B12/100)*Допущения!$B$69 -> 5843.5 | C21: =(Допущения!$B$68+$B$9*C12/100)*Допущения!$B$69 -> 6742.5 | D21: =(Допущения!$B$68+$B$9*D12/100)*Допущения!$B$69 -> 9889 | E21: =(Допущения!$B$68+$B$9*E12/100)*Допущения!$B$69 -> 18879
A22: IP, ₽/мес | B22: =Допущения!$B$70*Допущения!$B$71*730 -> 454.206 | C22: =Допущения!$B$70*Допущения!$B$71*730 -> 454.206 | D22: =Допущения!$B$70*Допущения!$B$71*730 -> 454.206 | E22: =Допущения!$B$70*Допущения!$B$71*730 -> 454.206
A23: S3, ₽/мес | B23: =B12*Тарифы!$D$7*Допущения!$B$49*Допущения!$B$50 -> 1180 | C23: =C12*Тарифы!$D$7*Допущения!$B$49*Допущения!$B$50 -> 3540 | D23: =D12*Тарифы!$D$7*Допущения!$B$49*Допущения!$B$50 -> 11800 | E23: =E12*Тарифы!$D$7*Допущения!$B$49*Допущения!$B$50 -> 35400
A24: Железо итого, ₽/мес | B24: =B20+B21+B22+B23 -> 56606.414 | C24: =C20+C21+C22+C23 -> 82984.806 | D24: =D20+D21+D22+D23 -> 204208.42 | E24: =E20+E21+E22+E23 -> 554690.06
A25: Модели, ₽/мес | B25: =B13*Себестоимость!$B$7 -> 331083.84 | C25: =C13*Себестоимость!$B$7 -> 993251.53 | D25: =D13*Себестоимость!$B$7 -> 3310838.4 | E25: =E13*Себестоимость!$B$7 -> 9932515.3
A26: Железо на клиента, ₽ | B26: =B24/B12 -> 566.06414 | C26: =C24/C12 -> 276.61602 | D26: =D24/D12 -> 204.20842 | E26: =E24/E12 -> 184.89669
A27: Модели на клиента, ₽ | B27: =B25/B12 -> 3310.8384 | C27: =C25/C12 -> 3310.8384 | D27: =D25/D12 -> 3310.8384 | E27: =E25/E12 -> 3310.8384
A29: На каждую 1 000 клиентов — ещё узел app (8 vCPU / 16 ГБ) и раннер ci (4 / 8); gitea — ещё узел на 3 000 клиентов.
